<?xml version="1.0" ?>

<robot name="robot" xmlns:xacro="http://www.ros.org/wiki/xacro">
    <xacro:include filename="$(find robot_description)/urdf/robot.gazebo" />
    
    <material name="blue">
        <color rgba="0 0 0.8 0.5"/>
    </material>

    <material name="black">
        <color rgba="0 0 0 0.8"/>
    </material>

    <material name="grey">
        <color rgba="0.5 0.5 0.5 0.5"/>
    </material>

    <!-- Link - chassis -->
    <link name="link_chassis">
        <inertial>
            <mass value="10" />
            <origin xyz="0 0 0.3" rpy="0 0 0" />
            <inertia ixx="1.5417" ixy="0" ixz="0" iyy="3.467" iyz="0" izz="4.742" />
        </inertial>

        <collision>
            <geometry>
                <box size="2 1.3 0.4" />
            </geometry>
        </collision>

        <visual>
            <geometry>
                <box size="2 1.3 0.4" />
            </geometry>
            <material name="blue"/>
        </visual>   
        
    </link>

            <!-- Joint - chassis / left wheel -->
        <joint name="joint_chassis_left_wheel" type="continuous">
            <origin rpy="0 0 0" xyz="-0.5 0.65 0" />
            <child link="link_left_wheel" />
            <parent link="link_chassis" />
            <axis rpy="0 0 0" xyz="0 1 0" />
            <limit effort="10000" velocity="1000" />
            <joint_properties damping="1.0" friction="1.0" />
        </joint>

        <joint name="joint_chassis_right_wheel" type="continuous">
            <origin rpy="0 0 0" xyz="-0.5 -0.65 0" />
            <child link="link_right_wheel" />
            <parent link="link_chassis" />
            <axis rpy="0 0 0" xyz="0 1 0" />
            <limit effort="10000" velocity="1000" />
            <joint_properties damping="1.0" friction="1.0" />
        </joint>

        <!-- Link - left wheel -->
        <link name="link_left_wheel">
            <inertial>
                <mass value="1" />
                <origin xyz="0 0 0" rpy="0 0 0" />
                <inertia ixx="0.002526666666667" ixy="0" ixz="0" iyy="0.002526666666667" iyz="0" izz="0.005"/>
            </inertial>

                <!-- Wheel -->
            <collision>
                <origin rpy="1.5708 0 0" xyz="0 0.18 0" />
                <geometry>
                    <cylinder length="0.12" radius="0.4"/>
                </geometry>
            </collision>
            <visual>
                <origin rpy="1.5708 0 0" xyz="0 0.18 0" />
                <geometry>
                    <cylinder length="0.12" radius="0.4"/>
                </geometry>
                <material name="black"/>
            </visual>

            <visual>
                <origin rpy="0 0 0" xyz="0 0.18 0" />
                <geometry>
                    <box size="0.1 1 0.5" />
                </geometry>
                <material name="grey"/>
            </visual>
            

                <!-- Shaft -->
            <collision>
                <origin rpy="1.5708 0 0" xyz="0 0.06 0" />
                <geometry>
                    <cylinder length="0.12" radius="0.08"/>
                </geometry>
            </collision>
            <visual>
                <origin rpy="1.5708 0 0" xyz="0 0.06 0" />
                <geometry>
                    <cylinder length="0.12" radius="0.08"/>
                </geometry>
                <material name="black"/>
            </visual>
        </link>


        <link name="link_right_wheel">
            <inertial>
                <mass value="1" />
                <origin xyz="0 0 0" rpy="0 0 0" />
                <inertia ixx="0.002526666666667" ixy="0" ixz="0" iyy="0.002526666666667" iyz="0" izz="0.005"/>
            </inertial>

                <!-- Wheel -->
            <collision>
                <origin rpy="1.5708 0 0" xyz="0 -0.18 0" />
                <geometry>
                    <cylinder length="0.12" radius="0.4"/>
                </geometry>
            </collision>
            <visual>
                <origin rpy="1.5708 0 0" xyz="0 -0.18 0" />
                <geometry>
                    <cylinder length="0.12" radius="0.4"/>
                </geometry>
                <material name="black"/>
            </visual>

            <visual>
                <origin rpy="0 0 0" xyz="0 -0.18 0" />
                <geometry>
                    <box size="0.1 1 0.5" />
                </geometry>
                <material name="grey"/>
            </visual>
            

                <!-- Shaft -->
            <collision>
                <origin rpy="1.5708 0 0" xyz="0 -0.06 0" />
                <geometry>
                    <cylinder length="0.12" radius="0.08"/>
                </geometry>
            </collision>
            <visual>
                <origin rpy="1.5708 0 0" xyz="0 -0.06 0" />
                <geometry>
                    <cylinder length="0.12" radius="0.08"/>
                </geometry>
                <material name="black"/>
            </visual>
        </link>

        






                <!-- Gazebo tags - Laser scan -->
        <gazebo reference="joint_laser_scan_chassis">
            <preserveFixedJoint>true</preserveFixedJoint>
        </gazebo>
        <gazebo reference="link_laser_scan">
            <material>Gazebo/DarkGrey</material>
        </gazebo>
        <!-- Laser scan -->
        <joint name="joint_laser_scan_chassis" type="fixed">
            <origin rpy="0 0 0" xyz="0.8 0 0.3" />
            <child link="link_laser_scan" />
            <parent link="link_chassis" />
            <joint_properties damping="1.0" friction="1.0" />
        </joint>
        <link name="link_laser_scan">
            <inertial>
                <origin xyz="0 0 0" rpy="0 0 0" />
                <mass value="0.5" />
                <inertia ixx="0.000252666666667" ixy="0" ixz="0" iyy="0.000252666666667" iyz="0" izz="0.0005"/>
            </inertial>
            <visual>
                <origin xyz="0 0 0" rpy="0 0 0" />
                <geometry>
                    <cylinder radius="0.15" length="0.20"/>
                </geometry>
                <material name="Red">
                    <color rgba="0.7 0.1 0.1 1" />
                </material>
            </visual>
            <collision>
                <origin xyz="0 0 0" rpy="0 0 0"/>
                <geometry>
                    <cylinder radius="0.15" length="0.20"/>
                </geometry>
            </collision>
        </link>
</robot>