<?xml version="1.0" ?>

<robot name="robot" xmlns:xacro="http://www.ros.org/wiki/xacro">
    <xacro:include filename="$(find project01)/urdf/robot.gazebo" />
    <xacro:property name="PI" value="3.1415926535"/>

    <material name="blue">
        <color rgba="0 0 0.8 0.8"/>
    </material>

    <material name="black">
        <color rgba="0 0 0 1"/>
    </material>

    <material name="grey">
        <color rgba="0.5 0.5 0.5 1"/>
    </material>

    <!-- Link - chassis (Model Body) -->
    <link name="link_chassis">
        <inertial>
            <mass value="10" />
            <origin xyz="0 0 0.3" rpy="0 0 0" />
            <inertia ixx="1.5417" ixy="0" ixz="0" iyy="3.467" iyz="0" izz="4.742" />
        </inertial>

        <collision>
            <geometry>
                <mesh filename="package://robot_description/meshes/chassis.stl" />
            </geometry>
        </collision>

        <visual>
            <geometry>
                <mesh filename="package://robot_description/meshes/chassis.stl" />
            </geometry>
            <material name="blue"/>
        </visual>   
    </link>

    <!-- Joint - chassis / Wheel -->
    <joint name="joint_chassis_left_wheel" type="continuous">
        <origin rpy="0 0 0" xyz="-0.5 0.65 0" />
        <child link="link_left_wheel" />
        <parent link="link_chassis" />
        <axis rpy="0 0 0" xyz="0 1 0" />
        <limit effort="10000" velocity="1000" />
        <joint_properties damping="1.0" friction="1.0" />
    </joint>
    <joint name="joint_chassis_right_wheel" type="continuous">
        <origin rpy="0 0 0" xyz="-0.5 -0.65 0" />
        <child link="link_right_wheel" />
        <parent link="link_chassis" />
        <axis rpy="0 0 0" xyz="0 1 0" />
        <limit effort="10000" velocity="1000" />
        <joint_properties damping="1.0" friction="1.0" />
    </joint>
    <joint name="joint_chassis_front_left_wheel" type="continuous">
        <origin rpy="0 0 0" xyz="0.5 0.83 0" />
        <child link="link_front_left_wheel" />
        <parent link="link_chassis" />
        <axis rpy="0 0 0" xyz="0 0 1" />
        <limit effort="10000" velocity="1000" />
        <joint_properties damping="1.0" friction="1.0" />
    </joint>
    <joint name="joint_chassis_front_right_wheel" type="continuous">
        <origin rpy="0 0 0" xyz="0.5 -0.83 0" />
        <child link="link_front_right_wheel" />
        <parent link="link_chassis" />
        <axis rpy="0 0 0" xyz="0 0 1" />
        <limit effort="10000" velocity="1000" />
        <joint_properties damping="1.0" friction="1.0" />
    </joint>
    
    <link name="link_left_wheel">
        <inertial>
            <mass value="1" />
            <origin xyz="0 0 0" rpy="0 0 0" />
            <inertia ixx="0.002526666666667" ixy="0" ixz="0" iyy="0.002526666666667" iyz="0" izz="0.005"/>
        </inertial>

            <!-- Wheel -->
        <collision>
            <origin rpy="${PI/2} 0 0" xyz="0 0.18 0" />
            <geometry>
                <mesh filename="package://robot_description/meshes/wheel.stl" />
            </geometry>
        </collision>
        <visual>
            <origin rpy="${PI/2} 0 0" xyz="0 0.18 0" />
            <geometry>
                <mesh filename="package://robot_description/meshes/wheel.stl" />
            </geometry>
            <material name="black"/>
        </visual>

        <visual>
            <origin rpy="0 0 0" xyz="0 0.18 0" />
            <geometry>
                <box size="0.1 0.1 0.7" />
            </geometry>
            <material name="grey"/>
        </visual>
        

            <!-- Shaft -->
        <collision>
            <origin rpy="${PI/2} 0 0" xyz="0 0.06 0" />
            <geometry>
                <cylinder length="0.12" radius="0.08"/>
            </geometry>
        </collision>
        <visual>
            <origin rpy="${PI/2} 0 0" xyz="0 0.06 0" />
            <geometry>
                <cylinder length="0.12" radius="0.08"/>
            </geometry>
        </visual>
    </link>
    <link name="link_right_wheel">
        <inertial>
            <mass value="1" />
            <origin xyz="0 0 0" rpy="0 0 0" />
            <inertia ixx="0.002526666666667" ixy="0" ixz="0" iyy="0.002526666666667" iyz="0" izz="0.005"/>
        </inertial>

            <!-- Wheel -->
        <collision>
            <origin rpy="${PI/2} 0 0" xyz="0 -0.18 0" />
            <geometry>
                <mesh filename="package://robot_description/meshes/wheel.stl" />
            </geometry>
        </collision>
        <visual>
            <origin rpy="${PI/2} 0 0" xyz="0 -0.18 0" />
            <geometry>
                <mesh filename="package://robot_description/meshes/wheel.stl" />
            </geometry>
            <material name="black"/>
        </visual>

        <visual>
            <origin rpy="0 0 0" xyz="0 -0.18 0" />
            <geometry>
                <box size="0.1 0.1 0.7" />
            </geometry>
            <material name="grey"/>
        </visual>
        

            <!-- Shaft -->
        <collision>
            <origin rpy="${PI/2} 0 0" xyz="0 -0.06 0" />
            <geometry>
                <cylinder length="0.12" radius="0.08"/>
            </geometry>
        </collision>
        <visual>
            <origin rpy="${PI/2} 0 0" xyz="0 -0.06 0" />
            <geometry>
                <cylinder length="0.12" radius="0.08"/>
            </geometry>
        </visual>
    </link>
    <link name="link_front_left_wheel">
        <inertial>
            <mass value="1" />
            <origin xyz="0 0 0" rpy="0 0 0" />
            <inertia ixx="0.002526666666667" ixy="0" ixz="0" iyy="0.002526666666667" iyz="0" izz="0.005"/>
        </inertial>

            <!-- Wheel -->
        <collision>
            <origin rpy="${PI/2} 0 0" xyz="0 0 0" />
            <geometry>
                <mesh filename="package://robot_description/meshes/wheel.stl" />
            </geometry>
        </collision>
        <visual>
            <origin rpy="${PI/2} 0 0" xyz="0 0 0" />
            <geometry>
                <mesh filename="package://robot_description/meshes/wheel.stl" />
            </geometry>
            <material name="black"/>
        </visual>

        <visual>
            <origin rpy="0 0 0" xyz="0 0 0" />
            <geometry>
                <box size="0.1 0.1 0.7" />
            </geometry>
            <material name="grey"/>
        </visual>
            <!-- Shaft -->
        <collision>
            <origin rpy="${PI/2} 0 0" xyz="0 -0.12 0" />
            <geometry>
                <cylinder length="0.12" radius="0.08"/>
            </geometry>
        </collision>
    </link>
    <link name="link_front_right_wheel">
        <inertial>
            <mass value="1" />
            <origin xyz="0 0 0" rpy="0 0 0" />
            <inertia ixx="0.002526666666667" ixy="0" ixz="0" iyy="0.002526666666667" iyz="0" izz="0.005"/>
        </inertial>

            <!-- Wheel -->
        <collision>
            <origin rpy="${PI/2} 0 0" xyz="0 0 0" />
            <geometry>
                <mesh filename="package://robot_description/meshes/wheel.stl" />
            </geometry>
        </collision>
        <visual>
            <origin rpy="${PI/2} 0 0" xyz="0 0 0" />
            <geometry>
                <mesh filename="package://robot_description/meshes/wheel.stl" />
            </geometry>
            <material name="black"/>
        </visual>

        <visual>
            <origin rpy="0 0 0" xyz="0 0 0" />
            <geometry>
                <box size="0.1 0.1 0.7" />
            </geometry>
            <material name="grey"/>
        </visual>
        
    </link>




    <!-- Gazebo tags - Laser scan -->
    <gazebo reference="joint_laser_scan_chassis">
        <preserveFixedJoint>true</preserveFixedJoint>
    </gazebo>
    <gazebo reference="link_laser_scan">
        <material>Gazebo/DarkGrey</material>
    </gazebo>
    <!-- Laser scan -->
    <joint name="joint_laser_scan_chassis" type="fixed">
        <origin rpy="0 0 0" xyz="0.8 0 0.3" />
        <child link="link_laser_scan" />
        <parent link="link_chassis" />
        <joint_properties damping="1.0" friction="1.0" />
    </joint>
    <link name="link_laser_scan">
        <inertial>
            <origin xyz="0 0 0" rpy="0 0 0" />
            <mass value="0.5" />
            <inertia ixx="0.000252666666667" ixy="0" ixz="0" iyy="0.000252666666667" iyz="0" izz="0.0005"/>
        </inertial>
        <visual>
            <origin xyz="0 0 0" rpy="0 0 0" />
            <geometry>
                <cylinder radius="0.15" length="0.20"/>
            </geometry>
            <material name="black"/>
        </visual>
        <collision>
            <origin xyz="0 0 0" rpy="0 0 0"/>
            <geometry>
                <cylinder radius="0.15" length="0.20"/>
            </geometry>
        </collision>
    </link>
    <transmission name="tran_front_left_wheel">
        <type>transmission_interface/SimpleTransmission</type>
        <joint name="joint_chassis_front_left_wheel">
            <hardwareInterface>hardware_interface/EffortJointInterface</hardwareInterface>
        </joint>
        <actuator name="motor_front_left_wheel">
            <hardwareInterface>hardware_interface/EffortJointInterface</hardwareInterface>
            <mechanicalReduction>1</mechanicalReduction>
        </actuator>
    </transmission>

    <transmission name="tran_front_right_wheel">
        <type>transmission_interface/SimpleTransmission</type>
        <joint name="joint_chassis_front_right_wheel">
            <hardwareInterface>hardware_interface/EffortJointInterface</hardwareInterface>
        </joint>
        <actuator name="motor_front_right_wheel">
            <hardwareInterface>hardware_interface/EffortJointInterface</hardwareInterface>
            <mechanicalReduction>1</mechanicalReduction>
        </actuator>
    </transmission>

</robot>